<?xml version="1.0" encoding="utf-8"?>
<!-- This URDF was automatically created by SolidWorks to URDF Exporter! Originally created by Stephen Brawner (brawner@gmail.com) 
     Commit Version: 1.6.0-1-g15f4949  Build Version: 1.6.7594.29634
     For more information, please see http://wiki.ros.org/sw_urdf_exporter -->
<robot
  name="5_6_4">
  <link
    name="base_link">
    <inertial>
      <origin
        xyz="-0.0021644 -0.013847 0.049054"
        rpy="0 0 0" />
      <mass
        value="2.4642" />
      <inertia
        ixx="0.007526"
        ixy="1.2162E-06"
        ixz="-8.7953E-08"
        iyy="0.0064842"
        iyz="-7.6062E-07"
        izz="0.013781" />
    </inertial>
    <visual>
      <origin
        xyz="0 0 0"
        rpy="0 0 0" />
      <geometry>
        <mesh
          filename="/home/me492/Capstone1_2021Spring_origin/src/Capstone1_2021Spring/coppeliasim_models/5_6_4/meshes/base_link.STL" />
      </geometry>
      <material
        name="">
        <color
          rgba="0.75294 0.75294 0.75294 1" />
      </material>
    </visual>
    <collision>
      <origin
        xyz="0 0 0"
        rpy="0 0 0" />
      <geometry>
        <mesh
          filename="/home/me492/Capstone1_2021Spring_origin/src/Capstone1_2021Spring/coppeliasim_models/5_6_4/meshes/base_link.STL" />
      </geometry>
    </collision>
  </link>
  <link
    name="LFWheel">
    <inertial>
      <origin
        xyz="-0.012331 -2.0514E-05 6.2467E-07"
        rpy="0 0 0" />
      <mass
        value="0.19333" />
      <inertia
        ixx="0.00025298"
        ixy="4.6921E-08"
        ixz="-1.4293E-09"
        iyy="0.00013675"
        iyz="-1.608E-09"
        izz="0.00013672" />
    </inertial>
    <visual>
      <origin
        xyz="0 0 0"
        rpy="0 0 0" />
      <geometry>
        <mesh
          filename="/home/me492/Capstone1_2021Spring_origin/src/Capstone1_2021Spring/coppeliasim_models/5_6_4/meshes/LFWheel.STL" />
      </geometry>
      <material
        name="">
        <color
          rgba="1 1 1 1" />
      </material>
    </visual>
    <collision>
      <origin
        xyz="0 0 0"
        rpy="0 0 0" />
      <geometry>
        <mesh
          filename="/home/me492/Capstone1_2021Spring_origin/src/Capstone1_2021Spring/coppeliasim_models/5_6_4/meshes/LFWheel.STL" />
      </geometry>
    </collision>
  </link>
  <joint
    name="Main2LFWheel"
    type="continuous">
    <origin
      xyz="-0.1605 0.133 0.012197"
      rpy="1.5708 0 0" />
    <parent
      link="base_link" />
    <child
      link="LFWheel" />
    <axis
      xyz="1 0 0" />
    <limit
      effort="3.1"
      velocity="7" />
  </joint>
  <link
    name="LRWheel">
    <inertial>
      <origin
        xyz="-0.012331 -2.0514E-05 6.2467E-07"
        rpy="0 0 0" />
      <mass
        value="0.19333" />
      <inertia
        ixx="0.00025298"
        ixy="4.6921E-08"
        ixz="-1.4293E-09"
        iyy="0.00013675"
        iyz="-1.608E-09"
        izz="0.00013672" />
    </inertial>
    <visual>
      <origin
        xyz="0 0 0"
        rpy="0 0 0" />
      <geometry>
        <mesh
          filename="/home/me492/Capstone1_2021Spring_origin/src/Capstone1_2021Spring/coppeliasim_models/5_6_4/meshes/LRWheel.STL" />
      </geometry>
      <material
        name="">
        <color
          rgba="1 1 1 1" />
      </material>
    </visual>
    <collision>
      <origin
        xyz="0 0 0"
        rpy="0 0 0" />
      <geometry>
        <mesh
          filename="/home/me492/Capstone1_2021Spring_origin/src/Capstone1_2021Spring/coppeliasim_models/5_6_4/meshes/LRWheel.STL" />
      </geometry>
    </collision>
  </link>
  <joint
    name="Main2LRWheel"
    type="continuous">
    <origin
      xyz="-0.1605 -0.133 0.012199"
      rpy="1.5708 0 0" />
    <parent
      link="base_link" />
    <child
      link="LRWheel" />
    <axis
      xyz="1 0 0" />
    <limit
      effort="3.1"
      velocity="7" />
  </joint>
  <link
    name="RFWheel">
    <inertial>
      <origin
        xyz="-0.012331 -2.0507E-05 -8.2265E-07"
        rpy="0 0 0" />
      <mass
        value="0.19333" />
      <inertia
        ixx="0.00025298"
        ixy="4.6905E-08"
        ixz="1.8811E-09"
        iyy="0.00013675"
        iyz="4.5706E-10"
        izz="0.00013672" />
    </inertial>
    <visual>
      <origin
        xyz="0 0 0"
        rpy="0 0 0" />
      <geometry>
        <mesh
          filename="/home/me492/Capstone1_2021Spring_origin/src/Capstone1_2021Spring/coppeliasim_models/5_6_4/meshes/RFWheel.STL" />
      </geometry>
      <material
        name="">
        <color
          rgba="1 1 1 1" />
      </material>
    </visual>
    <collision>
      <origin
        xyz="0 0 0"
        rpy="0 0 0" />
      <geometry>
        <mesh
          filename="/home/me492/Capstone1_2021Spring_origin/src/Capstone1_2021Spring/coppeliasim_models/5_6_4/meshes/RFWheel.STL" />
      </geometry>
    </collision>
  </link>
  <joint
    name="Main2RFWheel"
    type="continuous">
    <origin
      xyz="0.1605 0.133 0.012199"
      rpy="2.7498 0 -3.1416" />
    <parent
      link="base_link" />
    <child
      link="RFWheel" />
    <axis
      xyz="1 0 0" />
    <limit
      effort="3.1"
      velocity="7" />
  </joint>
  <link
    name="RRWheel">
    <inertial>
      <origin
        xyz="-0.012331 -2.0514E-05 6.2467E-07"
        rpy="0 0 0" />
      <mass
        value="0.19333" />
      <inertia
        ixx="0.00025298"
        ixy="4.6921E-08"
        ixz="-1.4293E-09"
        iyy="0.00013675"
        iyz="-1.608E-09"
        izz="0.00013672" />
    </inertial>
    <visual>
      <origin
        xyz="0 0 0"
        rpy="0 0 0" />
      <geometry>
        <mesh
          filename="/home/me492/Capstone1_2021Spring_origin/src/Capstone1_2021Spring/coppeliasim_models/5_6_4/meshes/RRWheel.STL" />
      </geometry>
      <material
        name="">
        <color
          rgba="1 1 1 1" />
      </material>
    </visual>
    <collision>
      <origin
        xyz="0 0 0"
        rpy="0 0 0" />
      <geometry>
        <mesh
          filename="/home/me492/Capstone1_2021Spring_origin/src/Capstone1_2021Spring/coppeliasim_models/5_6_4/meshes/RRWheel.STL" />
      </geometry>
    </collision>
  </link>
  <joint
    name="Main2RRWheel"
    type="continuous">
    <origin
      xyz="0.1605 -0.133 0.012197"
      rpy="2.7498 0 3.1416" />
    <parent
      link="base_link" />
    <child
      link="RRWheel" />
    <axis
      xyz="1 0 0" />
    <limit
      effort="3.1"
      velocity="7" />
  </joint>
  <link
    name="GripperMain">
    <inertial>
      <origin
        xyz="0 0 0"
        rpy="0 0 0" />
      <mass
        value="0" />
      <inertia
        ixx="0"
        ixy="0"
        ixz="0"
        iyy="0"
        iyz="0"
        izz="0" />
    </inertial>
    <visual>
      <origin
        xyz="0 0 0"
        rpy="0 0 0" />
      <geometry>
        <mesh
          filename="/home/me492/Capstone1_2021Spring_origin/src/Capstone1_2021Spring/coppeliasim_models/5_6_4/meshes/GripperMain.STL" />
      </geometry>
      <material
        name="">
        <color
          rgba="1 1 1 1" />
      </material>
    </visual>
    <collision>
      <origin
        xyz="0 0 0"
        rpy="0 0 0" />
      <geometry>
        <mesh
          filename="/home/me492/Capstone1_2021Spring_origin/src/Capstone1_2021Spring/coppeliasim_models/5_6_4/meshes/GripperMain.STL" />
      </geometry>
    </collision>
  </link>
  <joint
    name="Main2GripperMain"
    type="prismatic">
    <origin
      xyz="-0.037952 -0.055001 0.012782"
      rpy="1.5708 0 -3.1416" />
    <parent
      link="base_link" />
    <child
      link="GripperMain" />
    <axis
      xyz="0 1 0" />
    <limit
      lower="-0.1"
      upper="0.2"
      effort="200"
      velocity="0.04" />
  </joint>
  <link
    name="GripperArm">
    <inertial>
      <origin
        xyz="-0.021174 -0.054432 -0.077171"
        rpy="0 0 0" />
      <mass
        value="0.088275" />
      <inertia
        ixx="0.00024973"
        ixy="4.4457E-06"
        ixz="2.215E-19"
        iyy="0.00016709"
        iyz="5.9716E-20"
        izz="8.5792E-05" />
    </inertial>
    <visual>
      <origin
        xyz="0 0 0"
        rpy="0 0 0" />
      <geometry>
        <mesh
          filename="/home/me492/Capstone1_2021Spring_origin/src/Capstone1_2021Spring/coppeliasim_models/5_6_4/meshes/GripperArm.STL" />
      </geometry>
      <material
        name="">
        <color
          rgba="1 1 1 0.32" />
      </material>
    </visual>
    <collision>
      <origin
        xyz="0 0 0"
        rpy="0 0 0" />
      <geometry>
        <mesh
          filename="/home/me492/Capstone1_2021Spring_origin/src/Capstone1_2021Spring/coppeliasim_models/5_6_4/meshes/GripperArm.STL" />
      </geometry>
    </collision>
  </link>
  <joint
    name="GripperMain2GripperArm"
    type="prismatic">
    <origin
      xyz="-0.10496 0.097218 0.35486"
      rpy="0 0.087266 0" />
    <parent
      link="GripperMain" />
    <child
      link="GripperArm" />
    <axis
      xyz="0.99619 0 0.087156" />
    <limit
      lower="-0.1"
      upper="0.2"
      effort="200"
      velocity="0.04" />
  </joint>
</robot>